Workbook

Sheet ①募集要項
B2: note ゼロイチ実証モニター 募集要項・参加条件
B3: ※ このシートは募集文の下書きです。実際の募集時にコピーして使用してください。
B5: 段階投入の設計
B6: 段階 | C6: 人数 | D6: 目的・扱い
B7: 0. 自分 | C7: 1名（本人） | D7: 新規0フォロワーアカウントで完走し、手順を体系化する。ここが終わるまでモニターは開始しない。
B8: 1. 第1陣 | C8: 3名 | D8: 教材の穴出しが目的。達成率は実証数字に含めない。募集時に「検証目的である」と明示する。
B9: 2. 改善 | C9: — | D9: 第1陣が詰まった箇所を教材・手順に反映する。
B10: 3. 第2陣 | C10: 7名 | D10: 本番。ここの達成率を実証数字として運営に提示する。
B12: 参加条件（すべて満たす方）
B13: # | C13: 条件 | D13: なぜこの条件が必要か
B14: 1 | C14: コンテンツ販売での売上が0円の方（ゼロイチ未達） | D14: 「ゼロイチを達成させた」という主張の前提。すでに売上がある人が達成しても証拠にならない。
B15: 2 | C15: noteの新規アカウントを用意できる方（フォロワー0から開始） | D15: 「フォロワー0から売れる」ことの証明に必須。既存アカウントでは再現性を主張できない。
B16: 3 | C16: 1日30分以上の作業時間を確保できる方（1週間） | D16: 「集中できる方」では主観になり測れない。時間で定義することで、そのまま低負荷の証拠になる。
B17: 4 | C17: Claudeのサブスクを契約できる方 | D17: AIツールの利用が前提のため。※自分の検証時に無料版で回るか確認し、可能なら条件から外す。
B18: 5 | C18: 実証ログを毎日提出できる方（Googleフォーム／所要2〜3分） | D18: 最優先の条件。ログが取れなければ実証そのものが成立しない。
B19: 6 | C19: 成果・体験談の公開に同意できる方（実名/ニックネーム/匿名は選択可） | D19: 事例として使用するため。後から依頼すると断られるので入口で取得する。
B21: 辞退・除外の扱い（募集時に明記）
B22: ・3日以上ログの提出および連絡がない場合は、辞退とみなし実証対象から除外します。
B23: ・除外者は達成率の母数から外し、その旨を実証結果に明記します（母数を操作しないため）。
B24: ・期間内に売上が発生しなかった場合も、ログは最後まで提出をお願いします（改善材料として最も価値があるため）。
B26: 参加者に約束すること
B27: ・手順書、AIツール、テンプレートの提供
B28: ・期間中の質問対応（詰まった箇所は必ず解消する）
B29: ・※ 具体的な提供内容・価格・サポート範囲は本人記入

Sheet ②設問設計
B2: 実証ログ 設問設計（Googleフォーム転記用）
B3: ※ フォームは3つ作成します：A=参加時プロフィール（1回）／B=日次ログ（毎日）／C=完了サマリ（終了時1回）
B5: フォームA｜参加時プロフィール（開始前に1回）
B6: # | C6: 設問 | D6: 回答形式 | E6: 選択肢 | F6: 何の証拠になるか
B7: 1 | C7: お名前（ニックネーム可） | D7: 記述 | F7: 識別用
B8: 2 | C8: 開始日 | D8: 日付 | F8: 経過日数の起点
B9: 3 | C9: 第何陣ですか | D9: 選択 | E9: 第1陣 / 第2陣 | F9: 陣別の達成率を出すため
B10: 4 | C10: 本業の形態 | D10: 選択 | E10: フルタイム勤務 / パート・アルバイト / 専業主婦・主夫 / 自営 / 無職・休職中 / その他 | F10: 「忙しい人でも達成できた」の裏付け
B11: 5 | C11: 1日に確保できる作業時間 | D11: 選択 | E11: 30分未満 / 30分〜1時間 / 1〜2時間 / 2時間以上 | F11: 低負荷であることの前提条件
B12: 6 | C12: 文章を書いた経験 | D12: 選択 | E12: ほぼない / SNS投稿程度 / ブログ経験あり / 仕事で日常的に書く | F12: 「文章未経験でもできた」の裏付け
B13: 7 | C13: noteの利用経験 | D13: 選択 | E13: 使ったことがない / 読むだけ / 無料記事を書いたことがある | F13: 開始地点の記録
B14: 8 | C14: これまでのコンテンツ販売の売上 | D14: 選択 | E14: 0円 / 1〜9,999円 / 1万円以上 | F14: ゼロイチ未達の確認（参加条件）
B15: 9 | C15: 開始時のフォロワー数 | D15: 数値 | F15: 0からの達成であることの証明
B16: 10 | C16: AIツールの使用経験 | D16: 選択 | E16: まったくない / 少し使ったことがある / 日常的に使う | F16: 「AI初心者でもできた」の裏付け
B17: 11 | C17: 販売する題材（ネタ）はありますか | D17: 選択 | E17: すでに決まっている / 候補はある / まったくない | F17: 題材ゼロの人でも到達できるかの検証
B19: フォームB｜日次ログ（毎日・所要2〜3分）
B20: # | C20: 設問 | D20: 回答形式 | E20: 選択肢 | F20: 何の証拠になるか
B21: 1 | C21: お名前（ニックネーム可） | D21: 記述 | F21: 個人の紐付け
B22: 2 | C22: 日付 | D22: 日付 | F22: 経過日数の算出
B23: 3 | C23: 何日目ですか | D23: 数値 | F23: 経過日数
B24: 4 | C24: 今日の作業時間 | D24: 選択 | E24: 30分未満 / 30分〜1時間 / 1〜2時間 / 2〜3時間 / 3時間以上 | F24: ★ 総作業時間の集計元。「労力が少ない」の唯一の証拠
B25: 5 | C25: 今日進めた工程（複数選択可） | D25: 選択(複数) | E25: 題材決め / 構成作成 / 本文作成 / タイトル・見出し / 価格設定 / 記事公開 / 告知・集客 / その他 | F25: どの工程に時間がかかるかの特定
B26: 6 | C26: AIで生成した文章の割合 | D26: 選択 | E26: ほぼ全部（90%以上） / 大半（70%程度） / 半分くらい / 一部（30%程度） / ほぼ使わなかった | F26: ★ AI活用度。「書けない人でもできる」の裏付け
B27: 7 | C27: AIの文章に手直しは必要でしたか | D27: 選択 | E27: ほぼそのまま使えた / 少し直した / 半分くらい直した / 大幅に直した / 使えず自分で書き直した | F27: ★ ツールの完成度。手直しが多ければ改善対象
B28: 8 | C28: 手直しした理由（複数選択可） | D28: 選択(複数) | E28: 自分の言葉になっていない / 内容が薄い / 事実と違う / 長すぎる・短すぎる / 構成が合わない / 手直しは不要だった | F28: プロンプト改善の直接材料
B29: 9 | C29: 今日つまずいた箇所 | D29: 記述 | F29: ★ 教材・FAQに直結する最重要データ
B30: 10 | C30: そのつまずきは解決しましたか | D30: 選択 | E30: 自力で解決 / 教材を見て解決 / 質問して解決 / 未解決のまま | F30: 教材だけで自走できるかの判定
B31: 11 | C31: 今日の負荷感 | D31: 選択 | E31: 余裕があった / ちょうどよかった / ややきつかった / かなりきつかった | F31: ★ 主観的負荷。「労力が少ない」のもう一つの証拠
B32: 12 | C32: 売上は発生しましたか | D32: 選択 | E32: まだ / 発生した | F32: ゼロイチ達成の判定
B33: 13 | C33: （発生した場合）金額と購入者数 | D33: 記述 | F33: 達成内容の記録
B35: フォームC｜完了サマリ（終了時に1回）
B36: # | C36: 設問 | D36: 回答形式 | E36: 選択肢 | F36: 何の証拠になるか
B37: 1 | C37: お名前（ニックネーム可） | D37: 記述 | F37: 識別用
B38: 2 | C38: ゼロイチを達成しましたか | D38: 選択 | E38: 達成した / 達成できなかった | F38: ★ 達成率の集計元
B39: 3 | C39: 初売上までの日数 | D39: 数値 | F39: ★「◯日で達成」の根拠
B40: 4 | C40: 初売上までの総作業時間（時間） | D40: 数値 | F40: ★「総作業◯時間」の根拠。日次ログと突き合わせて検証
B41: 5 | C41: 売上金額 / 購入者数 | D41: 記述 | F41: 達成内容
B42: 6 | C42: 最もつまずいた工程 | D42: 選択 | E42: 題材決め / 構成作成 / 本文作成 / 価格設定 / 記事公開 / 告知・集客 | F42: 教材の弱点特定
B43: 7 | C43: 教材で分かりにくかった点 | D43: 記述 | F43: 改善材料
B44: 8 | C44: 一番役に立った点 | D44: 記述 | F44: セールス材料
...

Sheet ③日次ログ
B2: 日次ログ 記録表
B3: ※ Googleフォームの回答をここに貼り付けて蓄積します。この表のデータは⑤実証結果集計には直接使いません（集計は④を参照）。
B5: 参加者 | C5: 日付 | D5: 日目 | E5: 作業時間 | F5: 進めた工程 | G5: AI生成割合 | H5: 手直しの程度 | I5: 手直しの理由 | J5: つまずいた箇所 | K5: 解決状況 | L5: 負荷感 | M5: 売上発生 | N5: 金額・購入者数

Sheet ④完了サマリ
B2: 完了サマリ 記録表（1人1行）
B3: ※ ⑤実証結果集計は、この表の5〜19行目を参照しています。行の挿入は19行目より上で行ってください。
B4: 参加者 | C4: 陣 | D4: 達成/未達 | E4: 初売上までの日数 | F4: 総作業時間(h) | G4: 売上金額 | H4: 購入者数 | I4: 開始時フォロワー | J4: 本業形態 | K4: 1日の確保時間 | L4: 文章経験 | M4: AI生成割合 | N4: 手直しの程度 | O4: 最もつまずいた工程 | P4: 推奨度(0-10) | Q4: 公開可否 | R4: 体験談 | S4: 補助:達成者の日数 | T4: 補助:達成者の作業時間
S5: =IF($D5="達成",$E5,"") | T5: =IF($D5="達成",$F5,"")
S6: =IF($D6="達成",$E6,"") | T6: =IF($D6="達成",$F6,"")
S7: =IF($D7="達成",$E7,"") | T7: =IF($D7="達成",$F7,"")
S8: =IF($D8="達成",$E8,"") | T8: =IF($D8="達成",$F8,"")
S9: =IF($D9="達成",$E9,"") | T9: =IF($D9="達成",$F9,"")
S10: =IF($D10="達成",$E10,"") | T10: =IF($D10="達成",$F10,"")
S11: =IF($D11="達成",$E11,"") | T11: =IF($D11="達成",$F11,"")
S12: =IF($D12="達成",$E12,"") | T12: =IF($D12="達成",$F12,"")
S13: =IF($D13="達成",$E13,"") | T13: =IF($D13="達成",$F13,"")
S14: =IF($D14="達成",$E14,"") | T14: =IF($D14="達成",$F14,"")
S15: =IF($D15="達成",$E15,"") | T15: =IF($D15="達成",$F15,"")
S16: =IF($D16="達成",$E16,"") | T16: =IF($D16="達成",$F16,"")
... S19: =IF($D19="達成",$E19,"") | T19: =IF($D19="達成",$F19,"")
B21: 凡例：黄色セルが入力欄です。「陣」は「第1陣」「第2陣」、「達成/未達」は「達成」「未達」と入力してください（⑤の集計がこの表記を参照しています）。 | S21: 補助列S・Tは⑤実証結果集計の最短/最長の算出に使用します。手入力しないでください。

Sheet ⑤実証結果集計
B2: 実証結果 集計（運営提示用）
B3: ※ 数値は④完了サマリから自動計算されます。データ未入力の間は「-」と表示されます。
B5: 全体
B6: 指標 | C6: 値 | D6: 備考
B7: 参加者数（除外者を除く） | C7: =COUNTA('④完了サマリ'!B5:B19) | D7: ④に記録された人数
B8: 達成者数 | C8: =COUNTIF('④完了サマリ'!D5:D19,"達成")
B9: 達成率 | C9: =IF($C$7=0,"-",$C$8/$C$7) | D9: 運営提示時の中心指標
B10: 平均 初売上までの日数 | C10: =IF($C$8=0,"-",AVERAGEIFS('④完了サマリ'!E5:E19,'④完了サマリ'!D5:D19,"達成")) | D10: 達成者のみで算出
B11: 最短 初売上までの日数 | C11: =IF($C$8=0,"-",MIN('④完了サマリ'!S5:S19))
B12: 最長 初売上までの日数 | C12: =IF($C$8=0,"-",MAX('④完了サマリ'!S5:S19))
B13: 平均 総作業時間（時間） | C13: =IF($C$8=0,"-",AVERAGEIFS('④完了サマリ'!F5:F19,'④完了サマリ'!D5:D19,"達成")) | D13: ★ 差別化の中核指標
B14: 最短 総作業時間（時間） | C14: =IF($C$8=0,"-",MIN('④完了サマリ'!T5:T19))
B15: 平均 推奨度（0-10） | C15: =IF($C$8=0,"-",AVERAGEIFS('④完了サマリ'!P5:P19,'④完了サマリ'!D5:D19,"達成"))
B17: 陣別（改善効果を示す）
B18: 指標 | C18: 値 | D18: 備考
B19: 第1陣 参加者数 | C19: =COUNTIF('④完了サマリ'!C5:C19,"第1陣") | D19: 検証目的。達成率は実証数字に含めない
B20: 第1陣 達成者数 | C20: =COUNTIFS('④完了サマリ'!C5:C19,"第1陣",'④完了サマリ'!D5:D19,"達成")
B21: 第2陣 参加者数 | C21: =COUNTIF('④完了サマリ'!C5:C19,"第2陣") | D21: 改善後の本番
B22: 第2陣 達成者数 | C22: =COUNTIFS('④完了サマリ'!C5:C19,"第2陣",'④完了サマリ'!D5:D19,"達成")
B23: 第2陣 達成率 | C23: =IF(COUNTIFS('④完了サマリ'!C5:C19,"第2陣")=0,"-",COUNTIFS('④完了サマリ'!C5:C19,"第2陣",'④完了サマリ'!D5:D19,"達成")/COUNTIFS('④完了サマリ'!C5:C19,"第2陣")) | D23: ★ 運営に提示する数字はこれ
B25: 運営提示用サマリ（実証完了後に手書きで清書する）
B26: 例）フォロワー0の新規アカウントから、7名中◯名が◯日以内にnoteで初売上を達成。
B27: 平均総作業時間は◯時間。うち◯名はフルタイム勤務・文章未経験。
B28: 文章の◯割はAIが生成し、手直しは「少し直した」以下が◯名。
B29: ※ 上の数字は集計結果を転記して使用します。検証されていない数値を売り文句にしないこと
B30: （Step4-3「誇大な表現で煽って売る人、根拠のない約束をする人」に自分が該当しないため）。
